import exceptions

class TestError(exceptions.Exception):
    pass